Workbook

Sheet WA_Fn-UseC_-HR-Employee-Attriti
A1: Age | B1: Attrition | C1: BusinessTravel | D1: DailyRate | E1: Department | F1: DistanceFromHome | G1: Education | H1: EducationField | I1: EmployeeCount | J1: EmployeeNumber | K1: EnvironmentSatisfaction | L1: Gender | M1: HourlyRate | N1: JobInvolvement | O1: JobLevel | P1: JobRole | Q1: JobSatisfaction | R1: MaritalStatus | S1: MonthlyIncome | T1: MonthlyRate | U1: NumCompaniesWorked | V1: Over18 | W1: OverTime | X1: PercentSalaryHike | Y1: PerformanceRating | Z1: RelationshipSatisfaction | AA1: StandardHours | AB1: StockOptionLevel | AC1: TotalWorkingYears | AD1: TrainingTimesLastYear | AE1: WorkLifeBalance | AF1: YearsAtCompany | AG1: YearsInCurrentRole | AH1: YearsSinceLastPromotion | AI1: YearsWithCurrManager
A2: 41 | B2: Yes | C2: Travel_Rarely | D2: 1102 | E2: Sales | F2: 1 | G2: 2 | H2: Life Sciences | I2: 1 | J2: 1 | K2: 2 | L2: Female | M2: 94 | N2: 3 | O2: 2 | P2: Sales Executive | Q2: 4 | R2: Single | S2: 5993 | T2: 19479 | U2: 8 | V2: Y | W2: Yes | X2: 11 | Y2: 3 | Z2: 1 | AA2: 80 | AB2: 0 | AC2: 8 | AD2: 0 | AE2: 1 | AF2: 6 | AG2: 4 | AH2: 0 | AI2: 5
A3: 49 | B3: No | C3: Travel_Frequently | D3: 279 | E3: Research & Development | F3: 8 | G3: 1 | H3: Life Sciences | I3: 1 | J3: 2 | K3: 3 | L3: Male | M3: 61 | N3: 2 | O3: 2 | P3: Research Scientist | Q3: 2 | R3: Married | S3: 5130 | T3: 24907 | U3: 1 | V3: Y | W3: No | X3: 23 | Y3: 4 | Z3: 4 | AA3: 80 | AB3: 1 | AC3: 10 | AD3: 3 | AE3: 3 | AF3: 10 | AG3: 7 | AH3: 1 | AI3: 7
A4: 37 | B4: Yes | C4: Travel_Rarely | D4: 1373 | E4: Research & Development | F4: 2 | G4: 2 | H4: Other | I4: 1 | J4: 4 | K4: 4 | L4: Male | M4: 92 | N4: 2 | O4: 1 | P4: Laboratory Technician | Q4: 3 | R4: Single | S4: 2090 | T4: 2396 | U4: 6 | V4: Y | W4: Yes | X4: 15 | Y4: 3 | Z4: 2 | AA4: 80 | AB4: 0 | AC4: 7 | AD4: 3 | AE4: 3 | AF4: 0 | AG4: 0 | AH4: 0 | AI4: 0
A5: 33 | B5: No | C5: Travel_Frequently | D5: 1392 | E5: Research & Development | F5: 3 | G5: 4 | H5: Life Sciences | I5: 1 | J5: 5 | K5: 4 | L5: Female | M5: 56 | N5: 3 | O5: 1 | P5: Research Scientist | Q5: 3 | R5: Married | S5: 2909 | T5: 23159 | U5: 1 | V5: Y | W5: Yes | X5: 11 | Y5: 3 | Z5: 3 | AA5: 80 | AB5: 0 | AC5: 8 | AD5: 3 | AE5: 3 | AF5: 8 | AG5: 7 | AH5: 3 | AI5: 0
A6: 27 | B6: No | C6: Travel_Rarely | D6: 591 | E6: Research & Development | F6: 2 | G6: 1 | H6: Medical | I6: 1 | J6: 7 | K6: 1 | L6: Male | M6: 40 | N6: 3 | O6: 1 | P6: Laboratory Technician | Q6: 2 | R6: Married | S6: 3468 | T6: 16632 | U6: 9 | V6: Y | W6: No | X6: 12 | Y6: 3 | Z6: 4 | AA6: 80 | AB6: 1 | AC6: 6 | AD6: 3 | AE6: 3 | AF6: 2 | AG6: 2 | AH6: 2 | AI6: 2
A7: 32 | B7: No | C7: Travel_Frequently | D7: 1005 | E7: Research & Development | F7: 2 | G7: 2 | H7: Life Sciences | I7: 1 | J7: 8 | K7: 4 | L7: Male | M7: 79 | N7: 3 | O7: 1 | P7: Laboratory Technician | Q7: 4 | R7: Single | S7: 3068 | T7: 11864 | U7: 0 | V7: Y | W7: No | X7: 13 | Y7: 3 | Z7: 3 | AA7: 80 | AB7: 0 | AC7: 8 | AD7: 2 | AE7: 2 | AF7: 7 | AG7: 7 | AH7: 3 | AI7: 6
A8: 59 | B8: No | C8: Travel_Rarely | D8: 1324 | E8: Research & Development | F8: 3 | G8: 3 | H8: Medical | I8: 1 | J8: 10 | K8: 3 | L8: Female | M8: 81 | N8: 4 | O8: 1 | P8: Laboratory Technician | Q8: 1 | R8: Married | S8: 2670 | T8: 9964 | U8: 4 | V8: Y | W8: Yes | X8: 20 | Y8: 4 | Z8: 1 | AA8: 80 | AB8: 3 | AC8: 12 | AD8: 3 | AE8: 2 | AF8: 1 | AG8: 0 | AH8: 0 | AI8: 0
A9: 30 | B9: No | C9: Travel_Rarely | D9: 1358 | E9: Research & Development | F9: 24 | G9: 1 | H9: Life Sciences | I9: 1 | J9: 11 | K9: 4 | L9: Male | M9: 67 | N9: 3 | O9: 1 | P9: Laboratory Technician | Q9: 3 | R9: Divorced | S9: 2693 | T9: 13335 | U9: 1 | V9: Y | W9: No | X9: 22 | Y9: 4 | Z9: 2 | AA9: 80 | AB9: 1 | AC9: 1 | AD9: 2 | AE9: 3 | AF9: 1 | AG9: 0 | AH9: 0 | AI9: 0
A10: 38 | B10: No | C10: Travel_Frequently | D10: 216 | E10: Research & Development | F10: 23 | G10: 3 | H10: Life Sciences | I10: 1 | J10: 12 | K10: 4 | L10: Male | M10: 44 | N10: 2 | O10: 3 | P10: Manufacturing Director | Q10: 3 | R10: Single | S10: 9526 | T10: 8787 | U10: 0 | V10: Y | W10: No | X10: 21 | Y10: 4 | Z10: 2 | AA10: 80 | AB10: 0 | AC10: 10 | AD10: 2 | AE10: 3 | AF10: 9 | AG10: 7 | AH10: 1 | AI10: 8
A11: 36 | B11: No | C11: Travel_Rarely | D11: 1299 | E11: Research & Development | F11: 27 | G11: 3 | H11: Medical | I11: 1 | J11: 13 | K11: 3 | L11: Male | M11: 94 | N11: 3 | O11: 2 | P11: Healthcare Representative | Q11: 3 | R11: Married | S11: 5237 | T11: 16577 | U11: 6 | V11: Y | W11: No | X11: 13 | Y11: 3 | Z11: 2 | AA11: 80 | AB11: 2 | AC11: 17 | AD11: 3 | AE11: 2 | AF11: 7 | AG11: 7 | AH11: 7 | AI11: 7
A12: 35 | B12: No | C12: Travel_Rarely | D12: 809 | E12: Research & Development | F12: 16 | G12: 3 | H12: Medical | I12: 1 | J12: 14 | K12: 1 | L12: Male | M12: 84 | N12: 4 | O12: 1 | P12: Laboratory Technician | Q12: 2 | R12: Married | S12: 2426 | T12: 16479 | U12: 0 | V12: Y | W12: No | X12: 13 | Y12: 3 | Z12: 3 | AA12: 80 | AB12: 1 | AC12: 6 | AD12: 5 | AE12: 3 | AF12: 5 | AG12: 4 | AH12: 0 | AI12: 3
A13: 29 | B13: No | C13: Travel_Rarely | D13: 153 | E13: Research & Development | F13: 15 | G13: 2 | H13: Life Sciences | I13: 1 | J13: 15 | K13: 4 | L13: Female | M13: 49 | N13: 2 | O13: 2 | P13: Laboratory Technician | Q13: 3 | R13: Single | S13: 4193 | T13: 12682 | U13: 0 | V13: Y | W13: Yes | X13: 12 | Y13: 3 | Z13: 4 | AA13: 80 | AB13: 0 | AC13: 10 | AD13: 3 | AE13: 3 | AF13: 9 | AG13: 5 | AH13: 0 | AI13: 8
... A1471: 34 | B1471: No | C1471: Travel_Rarely | D1471: 628 | E1471: Research & Development | F1471: 8 | G1471: 3 | H1471: Medical | I1471: 1 | J1471: 2068 | K1471: 2 | L1471: Male | M1471: 82 | N1471: 4 | O1471: 2 | P1471: Laboratory Technician | Q1471: 3 | R1471: Married | S1471: 4404 | T1471: 10228 | U1471: 2 | V1471: Y | W1471: No | X1471: 12 | Y1471: 3 | Z1471: 1 | AA1471: 80 | AB1471: 0 | AC1471: 6 | AD1471: 3 | AE1471: 4 | AF1471: 4 | AG1471: 3 | AH1471: 1 | AI1471: 2

Sheet Pivot Analyze
A1: Sum of EmployeeCount | B1: Column Labels | E1: Attrition % | G1: Sum of EmployeeCount | H1: Column Labels
A2: Department | B2: Stayed | C2: Quit | D2: Grand Total | G2: Job satisfaction | H2: Stayed | I2: Quit | J2: Grand Total | K2: Attrition %
A3: Research & Development | B3: 828 | C3: 133 | D3: 961 | E3: =C3/D3 -> 0.1383975 | G3: 1 | H3: 223 | I3: 66 | J3: 289 | K3: =I3/J3 -> 0.2283737
A4: Sales | B4: 354 | C4: 92 | D4: 446 | E4: =C4/D4 -> 0.20627803 | G4: 2 | H4: 234 | I4: 46 | J4: 280 | K4: =I4/J4 -> 0.16428571
A5: Human Resources | B5: 51 | C5: 12 | D5: 63 | E5: =C5/D5 -> 0.19047619 | G5: 3 | H5: 369 | I5: 73 | J5: 442 | K5: =I5/J5 -> 0.16515837
A6: Grand Total | B6: 1233 | C6: 237 | D6: 1470 | G6: 4 | H6: 407 | I6: 52 | J6: 459 | K6: =I6/J6 -> 0.11328976
G7: Grand Total | H7: 1233 | I7: 237 | J7: 1470
N8: Department Attrition Analysis
A9: Average of MonthlyIncome | B9: Column Labels | G9: Sum of EmployeeCount | H9: Column Labels | N9: Compensation & Attrition Analysis
A10: Job Roles | B10: Stayed | C10: Quit | D10: Grand Total | G10: Environment satisfaction | H10: Stayed | I10: Quit | J10: Grand Total | K10: Attrition % | N10: Tenure & Attrition Analysis
A11: Manager | B11: 17201.485 | C11: 16797.4 | D11: 17181.676 | G11: 1 | H11: 212 | I11: 72 | J11: 284 | K11: =I11/J11 -> 0.25352113 | N11: Job Satisfaction & Attrition Analysis
A12: Research Director | B12: 15947.346 | C12: 19395.5 | D12: 16033.55 | G12: 2 | H12: 244 | I12: 43 | J12: 287 | K12: =I12/J12 -> 0.14982578 | N12: Environment Satisfaction & Attrition Analysis
A13: Healthcare Representative | B13: 7453.5574 | C13: 8548.2222 | D13: 7528.7634 | G13: 3 | H13: 391 | I13: 62 | J13: 453 | K13: =I13/J13 -> 0.13686534 | N13: Work-Life Balance & Attrition Analysis
A14: Manufacturing Director | B14: 7289.9259 | C14: 7365.5 | D14: 7295.1379 | G14: 4 | H14: 386 | I14: 60 | J14: 446 | K14: =I14/J14 -> 0.13452915 | N14: Overtime & Attrition Analysis
A15: Sales Executive | B15: 6804.6171 | C15: 7489 | D15: 6924.2791 | G15: Grand Total | H15: 1233 | I15: 237 | J15: 1470
A16: Human Resources | B16: 4391.75 | C16: 3715.75 | D16: 4235.75
A17: Laboratory Technician | B17: 3337.2234 | C17: 2919.2581 | D17: 3237.1699 | G17: Sum of EmployeeCount | H17: Column Labels
A18: Research Scientist | B18: 3328.1224 | C18: 2780.4681 | D18: 3239.9726 | G18: Work Life Balance | H18: Stayed | I18: Quit | J18: Grand Total | K18: Attrition %
A19: Sales Representative | B19: 2798.44 | C19: 2364.7273 | D19: 2626 | G19: 1 | H19: 55 | I19: 25 | J19: 80 | K19: =I19/J19 -> 0.3125
A20: Grand Total | B20: 6832.7397 | C20: 4787.0928 | D20: 6502.9313 | G20: 2 | H20: 286 | I20: 58 | J20: 344 | K20: =I20/J20 -> 0.16860465
G21: 3 | H21: 766 | I21: 127 | J21: 893 | K21: =I21/J21 -> 0.14221725
A22: Sum of EmployeeCount | B22: Column Labels | G22: 4 | H22: 126 | I22: 27 | J22: 153 | K22: =I22/J22 -> 0.17647059
A23: Years At Company | B23: Stayed | C23: Quit | D23: Grand Total | E23: Attrition % | G23: Grand Total | H23: 1233 | I23: 237 | J23: 1470
A24: 0 | B24: 28 | C24: 16 | D24: 44 | E24: =C24/D24 -> 0.36363636
A25: 1 | B25: 112 | C25: 59 | D25: 171 | E25: =C25/D25 -> 0.34502924 | G25: Sum of EmployeeCount | H25: Column Labels
A26: 2 | B26: 100 | C26: 27 | D26: 127 | E26: =C26/D26 -> 0.21259843 | G26: Overtime | H26: Stayed | I26: Quit | J26: Grand Total | K26: Attrition %
A27: 3 | B27: 108 | C27: 20 | D27: 128 | E27: =C27/D27 -> 0.15625 | G27: No overtime | H27: 944 | I27: 110 | J27: 1054 | K27: =I27/J27 -> 0.10436433
A28: 4 | B28: 91 | C28: 19 | D28: 110 | E28: =C28/D28 -> 0.17272727 | G28: Overtime | H28: 289 | I28: 127 | J28: 416 | K28: =I28/J28 -> 0.30528846
A29: 5 | B29: 175 | C29: 21 | D29: 196 | E29: =C29/D29 -> 0.10714286 | G29: Grand Total | H29: 1233 | I29: 237 | J29: 1470
A30: 6 | B30: 67 | C30: 9 | D30: 76 | E30: =C30/D30 -> 0.11842105
A31: 7 | B31: 79 | C31: 11 | D31: 90 | E31: =C31/D31 -> 0.12222222
A32: 8 | B32: 71 | C32: 9 | D32: 80 | E32: =C32/D32 -> 0.1125
A33: 9 | B33: 74 | C33: 8 | D33: 82 | E33: =C33/D33 -> 0.097560976
A34: 10 | B34: 102 | C34: 18 | D34: 120 | E34: =C34/D34 -> 0.15
A35: 11 | B35: 30 | C35: 2 | D35: 32 | E35: =C35/D35 -> 0.0625
A36: 12 | B36: 14 | D36: 14 | E36: =C36/D36 -> 0
A37: 13 | B37: 22 | C37: 2 | D37: 24 | E37: =C37/D37 -> 0.083333333
A38: 14 | B38: 16 | C38: 2 | D38: 18 | E38: =C38/D38 -> 0.11111111
A39: 15 | B39: 19 | C39: 1 | D39: 20 | E39: =C39/D39 -> 0.05
A40: 16 | B40: 11 | C40: 1 | D40: 12 | E40: =C40/D40 -> 0.083333333
...

Sheet Cleaned Data
A1: Age | B1: Attrition | C1: BusinessTravel | D1: DailyRate | E1: Department | F1: DistanceFromHome | G1: Education | H1: EducationField | I1: EmployeeNumber | J1: EnvironmentSatisfaction | K1: Gender | L1: HourlyRate | M1: JobInvolvement | N1: JobLevel | O1: JobRole | P1: JobSatisfaction | Q1: MaritalStatus | R1: MonthlyIncome | S1: MonthlyRate | T1: NumCompaniesWorked | U1: OverTime | V1: PercentSalaryHike | W1: PerformanceRating | X1: RelationshipSatisfaction | Y1: StockOptionLevel | Z1: TotalWorkingYears | AA1: TrainingTimesLastYear | AB1: WorkLifeBalance | AC1: YearsAtCompany | AD1: YearsInCurrentRole | AE1: YearsSinceLastPromotion | AF1: YearsWithCurrManager | AG1: AttritionFlag | AH1: OverTimeFlag | AI1: AgeBand | AJ1: MonthlyIncomeBand | AK1: TenureBand
A2: 41 | B2: Yes | C2: Travel Rarely | D2: 1102 | E2: Sales | F2: 1 | G2: 2 | H2: Life Sciences | I2: 1 | J2: 2 | K2: Female | L2: 94 | M2: 3 | N2: 2 | O2: Sales Executive | P2: 4 | Q2: Single | R2: 5993 | S2: 19479 | T2: 8 | U2: Yes | V2: 11 | W2: 3 | X2: 1 | Y2: 0 | Z2: 8 | AA2: 0 | AB2: 1 | AC2: 6 | AD2: 4 | AE2: 0 | AF2: 5 | AG2: 1 | AH2: 1 | AI2: 35-44 | AJ2: 3K-5.9K | AK2: 5-9 years
A3: 49 | B3: No | C3: Travel Frequently | D3: 279 | E3: Research & Development | F3: 8 | G3: 1 | H3: Life Sciences | I3: 2 | J3: 3 | K3: Male | L3: 61 | M3: 2 | N3: 2 | O3: Research Scientist | P3: 2 | Q3: Married | R3: 5130 | S3: 24907 | T3: 1 | U3: No | V3: 23 | W3: 4 | X3: 4 | Y3: 1 | Z3: 10 | AA3: 3 | AB3: 3 | AC3: 10 | AD3: 7 | AE3: 1 | AF3: 7 | AG3: 0 | AH3: 0 | AI3: 45-54 | AJ3: 3K-5.9K | AK3: 10+ years
A4: 37 | B4: Yes | C4: Travel Rarely | D4: 1373 | E4: Research & Development | F4: 2 | G4: 2 | H4: Other | I4: 4 | J4: 4 | K4: Male | L4: 92 | M4: 2 | N4: 1 | O4: Laboratory Technician | P4: 3 | Q4: Single | R4: 2090 | S4: 2396 | T4: 6 | U4: Yes | V4: 15 | W4: 3 | X4: 2 | Y4: 0 | Z4: 7 | AA4: 3 | AB4: 3 | AC4: 0 | AD4: 0 | AE4: 0 | AF4: 0 | AG4: 1 | AH4: 1 | AI4: 35-44 | AJ4: Under 3K | AK4: <2 years
A5: 33 | B5: No | C5: Travel Frequently | D5: 1392 | E5: Research & Development | F5: 3 | G5: 4 | H5: Life Sciences | I5: 5 | J5: 4 | K5: Female | L5: 56 | M5: 3 | N5: 1 | O5: Research Scientist | P5: 3 | Q5: Married | R5: 2909 | S5: 23159 | T5: 1 | U5: Yes | V5: 11 | W5: 3 | X5: 3 | Y5: 0 | Z5: 8 | AA5: 3 | AB5: 3 | AC5: 8 | AD5: 7 | AE5: 3 | AF5: 0 | AG5: 0 | AH5: 1 | AI5: 25-34 | AJ5: Under 3K | AK5: 5-9 years
A6: 27 | B6: No | C6: Travel Rarely | D6: 591 | E6: Research & Development | F6: 2 | G6: 1 | H6: Medical | I6: 7 | J6: 1 | K6: Male | L6: 40 | M6: 3 | N6: 1 | O6: Laboratory Technician | P6: 2 | Q6: Married | R6: 3468 | S6: 16632 | T6: 9 | U6: No | V6: 12 | W6: 3 | X6: 4 | Y6: 1 | Z6: 6 | AA6: 3 | AB6: 3 | AC6: 2 | AD6: 2 | AE6: 2 | AF6: 2 | AG6: 0 | AH6: 0 | AI6: 25-34 | AJ6: 3K-5.9K | AK6: 2-4 years
A7: 32 | B7: No | C7: Travel Frequently | D7: 1005 | E7: Research & Development | F7: 2 | G7: 2 | H7: Life Sciences | I7: 8 | J7: 4 | K7: Male | L7: 79 | M7: 3 | N7: 1 | O7: Laboratory Technician | P7: 4 | Q7: Single | R7: 3068 | S7: 11864 | T7: 0 | U7: No | V7: 13 | W7: 3 | X7: 3 | Y7: 0 | Z7: 8 | AA7: 2 | AB7: 2 | AC7: 7 | AD7: 7 | AE7: 3 | AF7: 6 | AG7: 0 | AH7: 0 | AI7: 25-34 | AJ7: 3K-5.9K | AK7: 5-9 years
A8: 59 | B8: No | C8: Travel Rarely | D8: 1324 | E8: Research & Development | F8: 3 | G8: 3 | H8: Medical | I8: 10 | J8: 3 | K8: Female | L8: 81 | M8: 4 | N8: 1 | O8: Laboratory Technician | P8: 1 | Q8: Married | R8: 2670 | S8: 9964 | T8: 4 | U8: Yes | V8: 20 | W8: 4 | X8: 1 | Y8: 3 | Z8: 12 | AA8: 3 | AB8: 2 | AC8: 1 | AD8: 0 | AE8: 0 | AF8: 0 | AG8: 0 | AH8: 1 | AI8: 55+ | AJ8: Under 3K | AK8: <2 years
A9: 30 | B9: No | C9: Travel Rarely | D9: 1358 | E9: Research & Development | F9: 24 | G9: 1 | H9: Life Sciences | I9: 11 | J9: 4 | K9: Male | L9: 67 | M9: 3 | N9: 1 | O9: Laboratory Technician | P9: 3 | Q9: Divorced | R9: 2693 | S9: 13335 | T9: 1 | U9: No | V9: 22 | W9: 4 | X9: 2 | Y9: 1 | Z9: 1 | AA9: 2 | AB9: 3 | AC9: 1 | AD9: 0 | AE9: 0 | AF9: 0 | AG9: 0 | AH9: 0 | AI9: 25-34 | AJ9: Under 3K | AK9: <2 years
A10: 38 | B10: No | C10: Travel Frequently | D10: 216 | E10: Research & Development | F10: 23 | G10: 3 | H10: Life Sciences | I10: 12 | J10: 4 | K10: Male | L10: 44 | M10: 2 | N10: 3 | O10: Manufacturing Director | P10: 3 | Q10: Single | R10: 9526 | S10: 8787 | T10: 0 | U10: No | V10: 21 | W10: 4 | X10: 2 | Y10: 0 | Z10: 10 | AA10: 2 | AB10: 3 | AC10: 9 | AD10: 7 | AE10: 1 | AF10: 8 | AG10: 0 | AH10: 0 | AI10: 35-44 | AJ10: 6K-9.9K | AK10: 5-9 years
A11: 36 | B11: No | C11: Travel Rarely | D11: 1299 | E11: Research & Development | F11: 27 | G11: 3 | H11: Medical | I11: 13 | J11: 3 | K11: Male | L11: 94 | M11: 3 | N11: 2 | O11: Healthcare Representative | P11: 3 | Q11: Married | R11: 5237 | S11: 16577 | T11: 6 | U11: No | V11: 13 | W11: 3 | X11: 2 | Y11: 2 | Z11: 17 | AA11: 3 | AB11: 2 | AC11: 7 | AD11: 7 | AE11: 7 | AF11: 7 | AG11: 0 | AH11: 0 | AI11: 35-44 | AJ11: 3K-5.9K | AK11: 5-9 years
A12: 35 | B12: No | C12: Travel Rarely | D12: 809 | E12: Research & Development | F12: 16 | G12: 3 | H12: Medical | I12: 14 | J12: 1 | K12: Male | L12: 84 | M12: 4 | N12: 1 | O12: Laboratory Technician | P12: 2 | Q12: Married | R12: 2426 | S12: 16479 | T12: 0 | U12: No | V12: 13 | W12: 3 | X12: 3 | Y12: 1 | Z12: 6 | AA12: 5 | AB12: 3 | AC12: 5 | AD12: 4 | AE12: 0 | AF12: 3 | AG12: 0 | AH12: 0 | AI12: 35-44 | AJ12: Under 3K | AK12: 5-9 years
A13: 29 | B13: No | C13: Travel Rarely | D13: 153 | E13: Research & Development | F13: 15 | G13: 2 | H13: Life Sciences | I13: 15 | J13: 4 | K13: Female | L13: 49 | M13: 2 | N13: 2 | O13: Laboratory Technician | P13: 3 | Q13: Single | R13: 4193 | S13: 12682 | T13: 0 | U13: Yes | V13: 12 | W13: 3 | X13: 4 | Y13: 0 | Z13: 10 | AA13: 3 | AB13: 3 | AC13: 9 | AD13: 5 | AE13: 0 | AF13: 8 | AG13: 0 | AH13: 1 | AI13: 25-34 | AJ13: 3K-5.9K | AK13: 5-9 years
... A1471: 34 | B1471: No | C1471: Travel Rarely | D1471: 628 | E1471: Research & Development | F1471: 8 | G1471: 3 | H1471: Medical | I1471: 2068 | J1471: 2 | K1471: Male | L1471: 82 | M1471: 4 | N1471: 2 | O1471: Laboratory Technician | P1471: 3 | Q1471: Married | R1471: 4404 | S1471: 10228 | T1471: 2 | U1471: No | V1471: 12 | W1471: 3 | X1471: 1 | Y1471: 0 | Z1471: 6 | AA1471: 3 | AB1471: 4 | AC1471: 4 | AD1471: 3 | AE1471: 1 | AF1471: 2 | AG1471: 0 | AH1471: 0 | AI1471: 25-34 | AJ1471: 3K-5.9K | AK1471: 2-4 years

Sheet Data Quality
A1: HR DATA QUALITY & PREPARATION REPORT
A2: Metric | B2: Result | D2: CODED SCALE GUIDE | E2: Meaning
A3: Source records | B3: 1470 | D3: Education | E3: 1 Below College; 2 College; 3 Bachelor; 4 Master; 5 Doctor
A4: Source columns | B4: 35 | D4: EnvironmentSatisfaction | E4: 1 Low; 2 Medium; 3 High; 4 Very High
A5: Analysis-ready columns | B5: 37 | D5: JobInvolvement | E5: 1 Low; 2 Medium; 3 High; 4 Very High
A6: Blank cells | B6: 0 | D6: JobSatisfaction | E6: 1 Low; 2 Medium; 3 High; 4 Very High
A7: Duplicate full records | B7: 0 | D7: PerformanceRating | E7: 3 Excellent; 4 Outstanding
A8: Duplicate EmployeeNumber values | B8: 0 | D8: RelationshipSatisfaction | E8: 1 Low; 2 Medium; 3 High; 4 Very High
A9: Tenure consistency issues | B9: 0 | D9: WorkLifeBalance | E9: 1 Bad; 2 Good; 3 Better; 4 Best
A10: Invalid category values | B10: 0 | D10: StockOptionLevel | E10: Ordinal level 0-3
A11: Fields removed (zero variance) | B11: EmployeeCount; Over18; StandardHours
A12: Category standardized | B12: BusinessTravel underscores replaced with spaces
A13: Derived fields added | B13: AttritionFlag; OverTimeFlag; AgeBand; MonthlyIncomeBand; TenureBand
A14: Status | B14: Ready for analysis

Sheet Dashboard
A1: HR ATTRITION ANALYSIS — KEY FINDINGS
A2: Employee attrition overview | 1,470 employee records | Analysis-ready summary
A4: OVERALL ATTRITION | D4: EMPLOYEES ANALYZED | G4: HIGHEST ATTRITION RATE | J4: OVERTIME ATTRITION
A5: ='Pivot Analyze'!C6/'Pivot Analyze'!D6 -> 0.16122449 | D5: ='Pivot Analyze'!D6 -> 1470 | G5: Sales | J5: ='Pivot Analyze'!I28/'Pivot Analyze'!J28 -> 0.30528846
A6: 237 employees left | D6: Complete workforce dataset | G6: =TEXT('Pivot Analyze'!E4,"0.00%")&" attrition" -> 20.63% attrition | J6: =TEXT('Pivot Analyze'!K27,"0.00%")&" without overtime" -> 10.44% without overtime
A8: WHAT THE DATA SAYS
A10: ="1. Department — Sales has the highest attrition rate at "&TEXT('Pivot Analyze'!E4,"0.00%")&", while Research & Development has the largest number of employees leaving ("&'Pivot Analyze'!C3&")." -> 1. Department — Sales has the highest attrition rate at 20.63%, while Research & Development has the largest number of employees leaving (133).
A11: ="2. Compensation — Employees who left earned "&TEXT('Pivot Analyze'!C20,"$#,##0")&" per month on average versus "&TEXT('Pivot Analyze'!B20,"$#,##0")&" among those who stayed." -> 2. Compensation — Employees who left earned $4,787 per month on average versus $6,833 among those who stayed.
A12: ="3. Tenure — Attrition is highest during the first two years, reaching "&TEXT('Pivot Analyze'!E24,"0%")&" at Year 0 and "&TEXT('Pivot Analyze'!E25,"0%")&" at Year 1." -> 3. Tenure — Attrition is highest during the first two years, reaching 36% at Year 0 and 35% at Year 1.
A13: ="4. Job Satisfaction — Employees with the lowest satisfaction had "&TEXT('Pivot Analyze'!K3,"0%")&" attrition, compared with "&TEXT('Pivot Analyze'!K6,"0%")&" among those with the highest satisfaction." -> 4. Job Satisfaction — Employees with the lowest satisfaction had 23% attrition, compared with 11% among those with the highest satisfaction.
A14: ="5. Environment Satisfaction — The lowest-rated group had "&TEXT('Pivot Analyze'!K11,"0%")&" attrition, compared with "&TEXT('Pivot Analyze'!K14,"0%")&" for the highest-rated group." -> 5. Environment Satisfaction — The lowest-rated group had 25% attrition, compared with 13% for the highest-rated group.
A15: 6. Work-Life Balance — The lowest-rated group had 31% attrition, compared with 17%, 14%, and 18% for the other ratings."
A16: ="7. Overtime — Employees working overtime had "&TEXT('Pivot Analyze'!K28,"0%")&" attrition, compared with "&TEXT('Pivot Analyze'!K27,"0%")&" among those who did not." -> 7. Overtime — Employees working overtime had 31% attrition, compared with 10% among those who did not.
A18: MANAGEMENT PRIORITIES
A19: 1. Review overtime workload and staffing, given the 31% attrition rate among overtime employees versus 10% among non-overtime employees.
A20: 2. Strengthen first-year onboarding and manager check-ins, given the 36% attrition at Year 0 and 35% at Year 1.
A21: 3. Investigate retention in Sales and among lower-satisfaction groups, particularly employees reporting low job satisfaction, environment satisfaction, or work-life balance.
